<?xml version="1.0" ?>
<!-- =================================================================================== -->
<!-- |    This document was autogenerated by xacro from tahoma.xacro                   | -->
<!-- |    EDITING THIS FILE BY HAND IS NOT RECOMMENDED                                 | -->
<!-- =================================================================================== -->
<robot name="tahoma">
  <link name="gripper_equilibrium_grasp"/>
  <joint name="gripper_base_link_gripper_equilibrium_grasp" type="fixed">
    <parent link="epick_end_effector"/>
    <child link="gripper_equilibrium_grasp"/>
    <origin rpy="0 0 0" xyz="0 0 0"/>
  </joint>
  <material name="blue_aluminum">
    <!-- more accurate but less pretty :) -->
    <!--color rgba=".14 .24 .31 1"/>
      <color rgba=".26 .44 .545 1"/-->
    <color rgba=".23 .42 .64 1"/>
  </material>
  <link name="stand">
    <inertial>
      <mass value="10.0"/>
      <inertia ixx="0.0002835" ixy="0.0" ixz="0.0" iyy="0.0002835" iyz="0.0" izz="0.000324"/>
    </inertial>
    <visual>
      <origin rpy="0 0 0" xyz="0 0 0"/>
      <geometry>
        <mesh filename="package://tahoma_description/meshes/stand/stand_base.stl"/>
      </geometry>
      <material name="blue_aluminum"/>
    </visual>
    <collision>
      <!-- across -->
      <origin rpy="0 0 0" xyz=".4050 0 .0281"/>
      <geometry>
        <box size=".09 1.53 .045"/>
      </geometry>
    </collision>
    <collision>
      <!-- right -->
      <origin rpy="0 0 0" xyz="0 -.72 -.0225"/>
      <geometry>
        <box size=".9 .09 .0562"/>
      </geometry>
    </collision>
    <collision>
      <!-- left -->
      <origin rpy="0 0 0" xyz="0 .72 -.0225"/>
      <geometry>
        <box size=".9 .09 .0562"/>
      </geometry>
    </collision>
  </link>
  <link name="stand_upright">
    <inertial>
      <mass value="34"/>
      <inertia ixx="0.0002835" ixy="0.0" ixz="0.0" iyy="0.0002835" iyz="0.0" izz="0.000324"/>
    </inertial>
    <visual>
      <origin rpy="0 0 0" xyz="0 0 0"/>
      <geometry>
        <mesh filename="package://tahoma_description/meshes/stand/stand_upright.stl"/>
      </geometry>
      <material name="blue_aluminum"/>
    </visual>
    <collision>
      <!-- right upright -->
      <origin rpy="0 0 0" xyz="-.1709 0.6975 0"/>
      <geometry>
        <box size=".2298 .0450 1.89"/>
      </geometry>
    </collision>
    <collision>
      <!-- left upright -->
      <origin rpy="0 0 0" xyz="-.1709 -0.6975 0"/>
      <geometry>
        <box size=".2298 .0450 1.89"/>
      </geometry>
    </collision>
    <collision>
      <!-- top beam -->
      <origin rpy="0 0 0" xyz="-.1733 0 .9012"/>
      <geometry>
        <box size=".2370 1.44 .0960"/>
      </geometry>
    </collision>
  </link>
  <link name="stand_brace">
    <inertial>
      <mass value="5"/>
      <inertia ixx="0.0002835" ixy="0.0" ixz="0.0" iyy="0.0002835" iyz="0.0" izz="0.000324"/>
    </inertial>
    <visual>
      <origin rpy="0 0 0" xyz="0 0 0"/>
      <geometry>
        <mesh filename="package://tahoma_description/meshes/stand/stand_brace.stl"/>
      </geometry>
      <material name="blue_aluminum"/>
    </visual>
    <collision>
      <origin rpy="0 0 0" xyz="0 0 0"/>
      <geometry>
        <box size=".102 1.4390 .4934"/>
      </geometry>
    </collision>
  </link>
  <link name="camera_beam_lower">
    <inertial>
      <mass value="5"/>
      <inertia ixx="0.0002835" ixy="0.0" ixz="0.0" iyy="0.0002835" iyz="0.0" izz="0.000324"/>
    </inertial>
    <visual>
      <origin rpy="0 0 0" xyz="0 0 0"/>
      <geometry>
        <mesh filename="package://tahoma_description/meshes/stand/camera_beam.stl"/>
      </geometry>
      <material name="blue_aluminum"/>
    </visual>
    <collision>
      <origin rpy="0 0 .022" xyz="0 0 0"/>
      <geometry>
        <box size="0.045 1.25 0.045"/>
      </geometry>
    </collision>
  </link>
  <link name="cantilever">
    <inertial>
      <mass value="8"/>
      <inertia ixx="0.0002835" ixy="0.0" ixz="0.0" iyy="0.0002835" iyz="0.0" izz="0.000324"/>
    </inertial>
    <visual>
      <origin rpy="0 0 0" xyz="0 0 0"/>
      <geometry>
        <mesh filename="package://tahoma_description/meshes/stand/cantilever.stl"/>
      </geometry>
      <material name="blue_aluminum"/>
    </visual>
    <collision>
      <origin xyz="0 0 .0415"/>
      <geometry>
        <box size=".7260 .225 .09"/>
      </geometry>
    </collision>
  </link>
  <link name="control_box_mount">
    <inertial>
      <mass value="3"/>
      <inertia ixx="0.0002835" ixy="0.0" ixz="0.0" iyy="0.0002835" iyz="0.0" izz="0.000324"/>
    </inertial>
    <visual>
      <origin rpy="0 0 0" xyz="0 0 0"/>
      <geometry>
        <mesh filename="package://tahoma_description/meshes/stand/control_box_mount.stl"/>
      </geometry>
      <material name="blue_aluminum"/>
    </visual>
    <collision>
      <origin rpy="0 0 0" xyz="0 0 0"/>
      <geometry>
        <box size=".585 .0602 .1790"/>
      </geometry>
    </collision>
  </link>
  <link name="control_box">
    <inertial>
      <mass value="7"/>
      <inertia ixx="0.0002835" ixy="0.0" ixz="0.0" iyy="0.0002835" iyz="0.0" izz="0.000324"/>
    </inertial>
    <visual>
      <origin rpy="0 0 0" xyz="0 0 0"/>
      <geometry>
        <mesh filename="package://tahoma_description/meshes/stand/control_box.stl"/>
      </geometry>
      <material name="aluminum"/>
    </visual>
    <collision>
      <origin rpy="0 0 0" xyz="0 0 0"/>
      <geometry>
        <box size=".46 .25 .44"/>
      </geometry>
    </collision>
  </link>
  <link name="robot_plate">
    <inertial>
      <mass value=".5"/>
      <inertia ixx="0.0002835" ixy="0.0" ixz="0.0" iyy="0.0002835" iyz="0.0" izz="0.000324"/>
    </inertial>
    <visual>
      <origin rpy="0 0 0" xyz="0 0 0"/>
      <geometry>
        <mesh filename="package://tahoma_description/meshes/stand/robot_plate.stl"/>
      </geometry>
      <material name="blue_aluminum"/>
    </visual>
    <collision>
      <origin rpy="0 0 0" xyz="0 0 0"/>
      <geometry>
        <box size=".225 .225 .0225"/>
      </geometry>
    </collision>
  </link>
  <!--material name="guard">
      <color rgba="1 .97 .89 1"/>
    </material-->
  <link name="front_right_caster">
    <inertial>
      <!-- Roughly caster, plate and bolts -->
      <mass value="1.0"/>
      <inertia ixx="0.0002835" ixy="0.0" ixz="0.0" iyy="0.0002835" iyz="0.0" izz="0.0002835"/>
    </inertial>
    <visual>
      <origin rpy="1.56 0 0" xyz="0 0 0"/>
      <geometry>
        <mesh filename="package://tahoma_description/meshes/stand/caster.stl"/>
      </geometry>
      <material name="wheel">
        <color rgba=".2 .2 .2 1"/>
      </material>
    </visual>
    <collision>
      <origin rpy="1.56 0 0" xyz="0 0 0"/>
      <geometry>
        <box size="0.09 0.1040 0.1225"/>
      </geometry>
    </collision>
  </link>
  <!--material name="guard">
      <color rgba="1 .97 .89 1"/>
    </material-->
  <link name="front_left_caster">
    <inertial>
      <!-- Roughly caster, plate and bolts -->
      <mass value="1.0"/>
      <inertia ixx="0.0002835" ixy="0.0" ixz="0.0" iyy="0.0002835" iyz="0.0" izz="0.0002835"/>
    </inertial>
    <visual>
      <origin rpy="1.56 0 0" xyz="0 0 0"/>
      <geometry>
        <mesh filename="package://tahoma_description/meshes/stand/caster.stl"/>
      </geometry>
      <material name="wheel">
        <color rgba=".2 .2 .2 1"/>
      </material>
    </visual>
    <collision>
      <origin rpy="1.56 0 0" xyz="0 0 0"/>
      <geometry>
        <box size="0.09 0.1040 0.1225"/>
      </geometry>
    </collision>
  </link>
  <!--material name="guard">
      <color rgba="1 .97 .89 1"/>
    </material-->
  <link name="back_left_caster">
    <inertial>
      <!-- Roughly caster, plate and bolts -->
      <mass value="1.0"/>
      <inertia ixx="0.0002835" ixy="0.0" ixz="0.0" iyy="0.0002835" iyz="0.0" izz="0.0002835"/>
    </inertial>
    <visual>
      <origin rpy="1.56 0 0" xyz="0 0 0"/>
      <geometry>
        <mesh filename="package://tahoma_description/meshes/stand/caster.stl"/>
      </geometry>
      <material name="wheel">
        <color rgba=".2 .2 .2 1"/>
      </material>
    </visual>
    <collision>
      <origin rpy="1.56 0 0" xyz="0 0 0"/>
      <geometry>
        <box size="0.09 0.1040 0.1225"/>
      </geometry>
    </collision>
  </link>
  <!--material name="guard">
      <color rgba="1 .97 .89 1"/>
    </material-->
  <link name="back_right_caster">
    <inertial>
      <!-- Roughly caster, plate and bolts -->
      <mass value="1.0"/>
      <inertia ixx="0.0002835" ixy="0.0" ixz="0.0" iyy="0.0002835" iyz="0.0" izz="0.0002835"/>
    </inertial>
    <visual>
      <origin rpy="1.56 0 0" xyz="0 0 0"/>
      <geometry>
        <mesh filename="package://tahoma_description/meshes/stand/caster.stl"/>
      </geometry>
      <material name="wheel">
        <color rgba=".2 .2 .2 1"/>
      </material>
    </visual>
    <collision>
      <origin rpy="1.56 0 0" xyz="0 0 0"/>
      <geometry>
        <box size="0.09 0.1040 0.1225"/>
      </geometry>
    </collision>
  </link>
  <link name="left_light_panel">
    <inertial>
      <mass value="1.0"/>
      <inertia ixx="0.0002835" ixy="0.0" ixz="0.0" iyy="0.0002835" iyz="0.0" izz="0.0002835"/>
    </inertial>
    <visual>
      <origin rpy="0 0 0" xyz="0 0 0"/>
      <geometry>
        <box size="1.21 .602 .01"/>
      </geometry>
      <material name="gray">
        <color rgba=".3 .3 .3 1"/>
      </material>
    </visual>
    <collision>
      <origin rpy="0 0 0" xyz="0 0 0"/>
      <geometry>
        <box size="1.21 .602 .01"/>
      </geometry>
    </collision>
  </link>
  <link name="left_light_panel_emitter">
    <visual>
      <origin rpy="0 0 0" xyz="0 0 .005"/>
      <geometry>
        <box size="1.17 .562 .00251"/>
      </geometry>
      <material name="white">
        <color rgba=".9 .9 .9 1"/>
      </material>
    </visual>
    <collision>
      <origin rpy="0 0 0" xyz="0 0 0"/>
      <geometry>
        <box size="1.17 .562 .00251"/>
      </geometry>
    </collision>
  </link>
  <joint name="left_light_panel_left_light_panel_emitter_joint" type="fixed">
    <parent link="left_light_panel"/>
    <child link="left_light_panel_emitter"/>
  </joint>
  <link name="right_light_panel">
    <inertial>
      <mass value="1.0"/>
      <inertia ixx="0.0002835" ixy="0.0" ixz="0.0" iyy="0.0002835" iyz="0.0" izz="0.0002835"/>
    </inertial>
    <visual>
      <origin rpy="0 0 0" xyz="0 0 0"/>
      <geometry>
        <box size="1.21 .602 .01"/>
      </geometry>
      <material name="gray">
        <color rgba=".3 .3 .3 1"/>
      </material>
    </visual>
    <collision>
      <origin rpy="0 0 0" xyz="0 0 0"/>
      <geometry>
        <box size="1.21 .602 .01"/>
      </geometry>
    </collision>
  </link>
  <link name="right_light_panel_emitter">
    <visual>
      <origin rpy="0 0 0" xyz="0 0 .005"/>
      <geometry>
        <box size="1.17 .562 .00251"/>
      </geometry>
      <material name="white">
        <color rgba=".9 .9 .9 1"/>
      </material>
    </visual>
    <collision>
      <origin rpy="0 0 0" xyz="0 0 0"/>
      <geometry>
        <box size="1.17 .562 .00251"/>
      </geometry>
    </collision>
  </link>
  <joint name="right_light_panel_right_light_panel_emitter_joint" type="fixed">
    <parent link="right_light_panel"/>
    <child link="right_light_panel_emitter"/>
  </joint>
  <joint name="stand_stand_upright_joint" type="fixed">
    <parent link="stand"/>
    <child link="stand_upright"/>
    <origin rpy="0 0 0" xyz="-.12 0 .95"/>
  </joint>
  <joint name="stand_upright_stand_brace_joint" type="fixed">
    <parent link="stand_upright"/>
    <child link="stand_brace"/>
    <origin rpy="0 0 0" xyz="-.24 0 -.59"/>
  </joint>
  <joint name="stand_upright_camera_beam_lower_joint" type="fixed">
    <parent link="stand_upright"/>
    <child link="camera_beam_lower"/>
    <origin rpy="0 0 0" xyz="-.1225 0 .193"/>
  </joint>
  <joint name="stand_upright_robot_control_box_mount_joint" type="fixed">
    <parent link="stand_upright"/>
    <child link="control_box_mount"/>
    <origin rpy="0 0 0" xyz="-.1725 .7475 .21"/>
  </joint>
  <joint name="control_box_mount_control_box_joint" type="fixed">
    <parent link="control_box_mount"/>
    <child link="control_box"/>
    <origin rpy="0.05 0 3.141592653589793" xyz="-.003 .1375 -0.13"/>
  </joint>
  <joint name="stand_cantilever_joint" type="fixed">
    <parent link="stand_upright"/>
    <child link="cantilever"/>
    <origin rpy="0 0 0" xyz=".0775 0  0.9442"/>
  </joint>
  <joint name="cantilever_robot_plate_joint" type="fixed">
    <parent link="cantilever"/>
    <child link="robot_plate"/>
    <origin rpy="0 0 0" xyz="0.2505 0 -.015"/>
  </joint>
  <joint name="stand_front_right_caster_joint" type="fixed">
    <parent link="stand"/>
    <child link="front_right_caster"/>
    <origin rpy="0 0 0" xyz=".405 -.7375 -0.1"/>
  </joint>
  <joint name="stand_front_left_caster_joint" type="fixed">
    <parent link="stand"/>
    <child link="front_left_caster"/>
    <origin rpy="0 0 0" xyz=".405 .7025 -0.1"/>
  </joint>
  <joint name="stand_back_right_caster_joint" type="fixed">
    <parent link="stand"/>
    <child link="back_right_caster"/>
    <origin rpy="0 0 0" xyz="-.405 -.7375 -0.1"/>
  </joint>
  <joint name="stand_back_left_caster_joint" type="fixed">
    <parent link="stand"/>
    <child link="back_left_caster"/>
    <origin rpy="0 0 0" xyz="-.405 .7025 -0.1"/>
  </joint>
  <joint name="stand_left_light_panel_joint" type="fixed">
    <parent link="stand_upright"/>
    <child link="left_light_panel"/>
    <origin rpy="0 1.5707963267948966 0" xyz="-.2625 .35 .25"/>
  </joint>
  <joint name="stand_left_right_panel_joint" type="fixed">
    <parent link="stand_upright"/>
    <child link="right_light_panel"/>
    <origin rpy="0 1.5707963267948966 0" xyz="-.2625 -.35 .25"/>
  </joint>
  <!--
    Base UR robot series xacro macro.

    NOTE: this is NOT a URDF. It cannot directly be loaded by consumers
    expecting a flattened '.urdf' file. See the top-level '.xacro' for that
    (but note: that .xacro must still be processed by the xacro command).

    For use in '.launch' files: use one of the 'load_urX.launch' convenience
    launch files.

    This file models the base kinematic chain of a UR robot, which then gets
    parameterised by various configuration files to convert it into a UR3(e),
    UR5(e), UR10(e) or UR16e.

    NOTE: the default kinematic parameters (ie: link lengths, frame locations,
    offets, etc) do not correspond to any particular robot. They are defaults
    only. There WILL be non-zero offsets between the Forward Kinematics results
    in TF (ie: robot_state_publisher) and the values reported by the Teach
    Pendant.

    For accurate (and robot-specific) transforms, the 'kinematics_parameters_file'
    parameter MUST point to a .yaml file containing the appropriate values for
    the targetted robot.

    If using the UniversalRobots/Universal_Robots_ROS_Driver, follow the steps
    described in the readme of that repository to extract the kinematic
    calibration from the controller and generate the required .yaml file.

    Main author of the migration to yaml configs: Ludovic Delval.

    Contributors to previous versions (in no particular order):

     - Felix Messmer
     - Kelsey Hawkins
     - Wim Meeussen
     - Shaun Edwards
     - Nadia Hammoudeh Garcia
     - Dave Hershberger
     - G. vd. Hoorn
     - Philip Long
     - Dave Coleman
     - Miguel Prada
     - Mathias Luedtke
     - Marcel Schnirring
     - Felix von Drigalski
     - Felix Exner
     - Jimmy Da Silva
     - Ajit Krisshna N L
     - Muhammad Asif Rana
  -->
  <!--
    NOTE: the macro defined in this file is NOT part of the public API of this
          package. Users CANNOT rely on this file being available, or stored in
          this location. Nor can they rely on the existence of the macro.
  -->
  <transmission name="arm_shoulder_pan_trans">
    <type>transmission_interface/SimpleTransmission</type>
    <joint name="arm_shoulder_pan_joint">
      <hardwareInterface>hardware_interface/PositionJointInterface</hardwareInterface>
    </joint>
    <actuator name="arm_shoulder_pan_motor">
      <mechanicalReduction>1</mechanicalReduction>
    </actuator>
  </transmission>
  <transmission name="arm_shoulder_lift_trans">
    <type>transmission_interface/SimpleTransmission</type>
    <joint name="arm_shoulder_lift_joint">
      <hardwareInterface>hardware_interface/PositionJointInterface</hardwareInterface>
    </joint>
    <actuator name="arm_shoulder_lift_motor">
      <mechanicalReduction>1</mechanicalReduction>
    </actuator>
  </transmission>
  <transmission name="arm_elbow_trans">
    <type>transmission_interface/SimpleTransmission</type>
    <joint name="arm_elbow_joint">
      <hardwareInterface>hardware_interface/PositionJointInterface</hardwareInterface>
    </joint>
    <actuator name="arm_elbow_motor">
      <mechanicalReduction>1</mechanicalReduction>
    </actuator>
  </transmission>
  <transmission name="arm_wrist_1_trans">
    <type>transmission_interface/SimpleTransmission</type>
    <joint name="arm_wrist_1_joint">
      <hardwareInterface>hardware_interface/PositionJointInterface</hardwareInterface>
    </joint>
    <actuator name="arm_wrist_1_motor">
      <mechanicalReduction>1</mechanicalReduction>
    </actuator>
  </transmission>
  <transmission name="arm_wrist_2_trans">
    <type>transmission_interface/SimpleTransmission</type>
    <joint name="arm_wrist_2_joint">
      <hardwareInterface>hardware_interface/PositionJointInterface</hardwareInterface>
    </joint>
    <actuator name="arm_wrist_2_motor">
      <mechanicalReduction>1</mechanicalReduction>
    </actuator>
  </transmission>
  <transmission name="arm_wrist_3_trans">
    <type>transmission_interface/SimpleTransmission</type>
    <joint name="arm_wrist_3_joint">
      <hardwareInterface>hardware_interface/PositionJointInterface</hardwareInterface>
    </joint>
    <actuator name="arm_wrist_3_motor">
      <mechanicalReduction>1</mechanicalReduction>
    </actuator>
  </transmission>
  <!-- links: main serial chain -->
  <link name="arm_base_link"/>
  <link name="arm_base_link_inertia">
    <visual>
      <origin rpy="0 0 3.141592653589793" xyz="0 0 0"/>
      <geometry>
        <mesh filename="package://ur_description/meshes/ur10e/visual/base.dae"/>
      </geometry>
      <material name="LightGrey">
        <color rgba="0.7 0.7 0.7 1.0"/>
      </material>
    </visual>
    <collision>
      <origin rpy="0 0 3.141592653589793" xyz="0 0 0"/>
      <geometry>
        <mesh filename="package://ur_description/meshes/ur10e/collision/base.stl"/>
      </geometry>
    </collision>
    <inertial>
      <mass value="4.0"/>
      <origin rpy="0 0 0" xyz="0 0 0"/>
      <inertia ixx="0.0061063308908" ixy="0.0" ixz="0.0" iyy="0.0061063308908" iyz="0.0" izz="0.01125"/>
    </inertial>
  </link>
  <link name="arm_shoulder_link">
    <visual>
      <origin rpy="0 0 3.141592653589793" xyz="0 0 0"/>
      <geometry>
        <mesh filename="package://ur_description/meshes/ur10e/visual/shoulder.dae"/>
      </geometry>
      <material name="LightGrey">
        <color rgba="0.7 0.7 0.7 1.0"/>
      </material>
    </visual>
    <collision>
      <origin rpy="0 0 3.141592653589793" xyz="0 0 0"/>
      <geometry>
        <mesh filename="package://ur_description/meshes/ur10e/collision/shoulder.stl"/>
      </geometry>
    </collision>
    <inertial>
      <mass value="7.369"/>
      <origin rpy="0 0 0" xyz="0 0 0"/>
      <inertia ixx="0.029819260655624295" ixy="0.0" ixz="0.0" iyy="0.029819260655624295" iyz="0.0" izz="0.020725312499999995"/>
    </inertial>
  </link>
  <link name="arm_upper_arm_link">
    <visual>
      <origin rpy="1.5707963267948966 0 -1.5707963267948966" xyz="0 0 0.176"/>
      <geometry>
        <mesh filename="package://ur_description/meshes/ur16e/visual/upperarm.dae"/>
      </geometry>
      <material name="LightGrey">
        <color rgba="0.7 0.7 0.7 1.0"/>
      </material>
    </visual>
    <collision>
      <origin rpy="1.5707963267948966 0 -1.5707963267948966" xyz="0 0 0.176"/>
      <geometry>
        <mesh filename="package://ur_description/meshes/ur16e/collision/upperarm.stl"/>
      </geometry>
    </collision>
    <inertial>
      <mass value="10.45"/>
      <origin rpy="0 1.5707963267948966 0" xyz="-0.2392 0.0 0.175"/>
      <inertia ixx="0.21399985623335657" ixy="0.0" ixz="0.0" iyy="0.21399985623335657" iyz="0.0" izz="0.029390624999999997"/>
    </inertial>
  </link>
  <link name="arm_forearm_link">
    <visual>
      <origin rpy="1.5707963267948966 0 -1.5707963267948966" xyz="0 0 0.04"/>
      <geometry>
        <mesh filename="package://ur_description/meshes/ur16e/visual/forearm.dae"/>
      </geometry>
      <material name="LightGrey">
        <color rgba="0.7 0.7 0.7 1.0"/>
      </material>
    </visual>
    <collision>
      <origin rpy="1.5707963267948966 0 -1.5707963267948966" xyz="0 0 0.04"/>
      <geometry>
        <mesh filename="package://ur_description/meshes/ur16e/collision/forearm.stl"/>
      </geometry>
    </collision>
    <inertial>
      <mass value="4.321"/>
      <origin rpy="0 1.5707963267948966 0" xyz="-0.18 0.0 0.04"/>
      <inertia ixx="0.052743185152717496" ixy="0.0" ixz="0.0" iyy="0.052743185152717496" iyz="0.0" izz="0.012152812499999997"/>
    </inertial>
  </link>
  <link name="arm_wrist_1_link">
    <visual>
      <!-- TODO: Move this to a parameter -->
      <origin rpy="1.5707963267948966 0 0" xyz="0 0 -0.135"/>
      <geometry>
        <mesh filename="package://ur_description/meshes/ur10e/visual/wrist1.dae"/>
      </geometry>
      <material name="LightGrey">
        <color rgba="0.7 0.7 0.7 1.0"/>
      </material>
    </visual>
    <collision>
      <origin rpy="1.5707963267948966 0 0" xyz="0 0 -0.135"/>
      <geometry>
        <mesh filename="package://ur_description/meshes/ur10e/collision/wrist1.stl"/>
      </geometry>
    </collision>
    <inertial>
      <mass value="2.18"/>
      <origin rpy="0 0 0" xyz="0 0 0"/>
      <inertia ixx="0.0056816227273499996" ixy="0.0" ixz="0.0" iyy="0.0056816227273499996" iyz="0.0" izz="0.00613125"/>
    </inertial>
  </link>
  <link name="arm_wrist_2_link">
    <visual>
      <origin rpy="0 0 0" xyz="0 0 -0.12"/>
      <geometry>
        <mesh filename="package://ur_description/meshes/ur10e/visual/wrist2.dae"/>
      </geometry>
      <material name="LightGrey">
        <color rgba="0.7 0.7 0.7 1.0"/>
      </material>
    </visual>
    <collision>
      <origin rpy="0 0 0" xyz="0 0 -0.12"/>
      <geometry>
        <mesh filename="package://ur_description/meshes/ur10e/collision/wrist2.stl"/>
      </geometry>
    </collision>
    <inertial>
      <mass value="2.033"/>
      <origin rpy="0 0 0" xyz="0 0 0"/>
      <inertia ixx="0.0052985041305975" ixy="0.0" ixz="0.0" iyy="0.0052985041305975" iyz="0.0" izz="0.0057178125"/>
    </inertial>
  </link>
  <link name="arm_wrist_3_link">
    <visual>
      <origin rpy="1.5707963267948966 0 0" xyz="0 0 -0.1168"/>
      <geometry>
        <mesh filename="package://ur_description/meshes/ur10e/visual/wrist3.dae"/>
      </geometry>
      <material name="LightGrey">
        <color rgba="0.7 0.7 0.7 1.0"/>
      </material>
    </visual>
    <collision>
      <origin rpy="1.5707963267948966 0 0" xyz="0 0 -0.1168"/>
      <geometry>
        <mesh filename="package://ur_description/meshes/ur10e/collision/wrist3.stl"/>
      </geometry>
    </collision>
    <inertial>
      <mass value="0.907"/>
      <origin rpy="0 0 0" xyz="0.0 0.0 -0.025"/>
      <inertia ixx="0.0006481268240825001" ixy="0.0" ixz="0.0" iyy="0.0006481268240825001" iyz="0.0" izz="0.0009183374999999999"/>
    </inertial>
  </link>
  <!-- joints: main serial chain -->
  <joint name="arm_base_link-base_link_inertia" type="fixed">
    <parent link="arm_base_link"/>
    <child link="arm_base_link_inertia"/>
    <!-- 'base_link' is REP-103 aligned (so X+ forward), while the internal
           frames of the robot/controller have X+ pointing backwards.
           Use the joint between 'base_link' and 'base_link_inertia' (a dummy
           link/frame) to introduce the necessary rotation over Z (of pi rad).
      -->
    <origin rpy="0 0 3.141592653589793" xyz="0 0 0"/>
  </joint>
  <joint name="arm_shoulder_pan_joint" type="revolute">
    <parent link="arm_base_link_inertia"/>
    <child link="arm_shoulder_link"/>
    <origin rpy="0 0 -5.226355219677126e-07" xyz="0 0 0.1808582427003927"/>
    <axis xyz="0 0 1"/>
    <limit effort="330.0" lower="-6.283185307179586" upper="6.283185307179586" velocity="2.0943951023931953"/>
    <dynamics damping="0" friction="0"/>
  </joint>
  <joint name="arm_shoulder_lift_joint" type="revolute">
    <parent link="arm_shoulder_link"/>
    <child link="arm_upper_arm_link"/>
    <origin rpy="1.571149055019948 0 -2.842156630394906e-06" xyz="0.0001146488038115345 0 0"/>
    <axis xyz="0 0 1"/>
    <limit effort="330.0" lower="-6.283185307179586" upper="6.283185307179586" velocity="2.0943951023931953"/>
    <dynamics damping="0" friction="0"/>
  </joint>
  <joint name="arm_elbow_joint" type="revolute">
    <parent link="arm_upper_arm_link"/>
    <child link="arm_forearm_link"/>
    <origin rpy="3.140966205585682 3.14143866526404 3.141584703118312" xyz="-0.478259666576996 0 0"/>
    <axis xyz="0 0 1"/>
    <limit effort="150.0" lower="-3.141592653589793" upper="3.141592653589793" velocity="3.141592653589793"/>
    <dynamics damping="0" friction="0"/>
  </joint>
  <joint name="arm_wrist_1_joint" type="revolute">
    <parent link="arm_forearm_link"/>
    <child link="arm_wrist_1_link"/>
    <origin rpy="0.006297130801998122 0.0009340032369312529 1.229979779393521e-06" xyz="-0.3600303731229585 -0.001096754867652125 0.1741650928407709"/>
    <axis xyz="0 0 1"/>
    <limit effort="56.0" lower="-6.283185307179586" upper="6.283185307179586" velocity="3.141592653589793"/>
    <dynamics damping="0" friction="0"/>
  </joint>
  <joint name="arm_wrist_2_joint" type="revolute">
    <parent link="arm_wrist_1_link"/>
    <child link="arm_wrist_2_link"/>
    <origin rpy="1.568915050891635 0 1.761825868220462e-06" xyz="5.900314979285639e-05 -0.1197777051587798 0.0002253351762985995"/>
    <axis xyz="0 0 1"/>
    <limit effort="56.0" lower="-6.283185307179586" upper="6.283185307179586" velocity="3.141592653589793"/>
    <dynamics damping="0" friction="0"/>
  </joint>
  <joint name="arm_wrist_3_joint" type="revolute">
    <parent link="arm_wrist_2_link"/>
    <child link="arm_wrist_3_link"/>
    <origin rpy="1.570124239363319 3.141592653589793 -3.141592198139823" xyz="9.510304711030174e-05 0.115763931390055 -7.780349503190604e-05"/>
    <axis xyz="0 0 1"/>
    <limit effort="56.0" lower="-6.283185307179586" upper="6.283185307179586" velocity="3.141592653589793"/>
    <dynamics damping="0" friction="0"/>
  </joint>
  <!-- ROS-Industrial 'base' frame: base_link to UR 'Base' Coordinates transform -->
  <link name="arm_base"/>
  <joint name="arm_base_link-base_fixed_joint" type="fixed">
    <!-- Note the rotation over Z of pi radians: as base_link is REP-103
           aligned (ie: has X+ forward, Y+ left and Z+ up), this is needed
           to correctly align 'base' with the 'Base' coordinate system of
           the UR controller.
      -->
    <origin rpy="0 0 3.141592653589793" xyz="0 0 0"/>
    <parent link="arm_base_link"/>
    <child link="arm_base"/>
  </joint>
  <!-- ROS-Industrial 'flange' frame: attachment point for EEF models -->
  <link name="arm_flange"/>
  <joint name="arm_wrist_3-flange" type="fixed">
    <parent link="arm_wrist_3_link"/>
    <child link="arm_flange"/>
    <origin rpy="0 -1.5707963267948966 -1.5707963267948966" xyz="0 0 0"/>
  </joint>
  <!-- ROS-Industrial 'tool0' frame: all-zeros tool frame -->
  <link name="arm_tool0"/>
  <joint name="arm_flange-tool0" type="fixed">
    <!-- default toolframe: X+ left, Y+ up, Z+ front -->
    <origin rpy="1.5707963267948966 0 1.5707963267948966" xyz="0 0 0"/>
    <parent link="arm_flange"/>
    <child link="arm_tool0"/>
  </joint>
  <link name="gripper_base_link">
    <inertial>
      <mass value="0.745"/>
      <origin rpy="0 0 0" xyz="0 0.0 0.055"/>
      <inertia ixx="0.003084" ixy="0.0" ixz="0.0" iyy="0.002999" iyz="0.0" izz="0.000546"/>
    </inertial>
    <visual>
      <origin rpy="0 0 1.5707963267948966" xyz="0 0 0.0485"/>
      <geometry>
        <mesh filename="package://robotiq_epick_visualization/meshes/visual/robotiq_epick.dae" scale="0.001 0.001 0.001"/>
      </geometry>
      <material name="mat1">
        <color rgba="1 1 1 1"/>
      </material>
    </visual>
    <visual>
      <origin rpy="0 0 0" xyz="0 0 0.137"/>
      <geometry>
        <cylinder length="0.08" radius="0.006"/>
      </geometry>
      <material name="mat2">
        <color rgba="1 0 0 1"/>
      </material>
    </visual>
    <!-- -0.095 + 0.102/2 = -0.044-->
    <!-- <visual>
        <origin xyz="0 0 ${-0.044+0.095+0.014+0.09}" rpy="0 0 0"/>
        <geometry>          
          <cylinder radius="0.006" length="0.09"/>
        </geometry>       
      </visual>  -->
    <collision>
      <!-- -0.095 + 0.102/2 = -0.044-->
      <origin rpy="0 0 0" xyz="0 0 0.057"/>
      <geometry>
        <cylinder length="0.114" radius="0.035"/>
      </geometry>
    </collision>
    <collision>
      <origin rpy="0 0 0" xyz="0 0 0.137"/>
      <geometry>
        <cylinder length="0.08" radius="0.006"/>
      </geometry>
      <material name="mat2">
        <color rgba="1 0 0 1"/>
      </material>
    </collision>
    <!-- -0.095 + 0.102/2 = -0.044-->
    <!-- <collision>
        <origin xyz="0 0 ${-0.044+0.095+0.014+0.09}" rpy="0 0 0"/>
        <geometry>          
          <cylinder radius="0.006" length="0.09"/>
        </geometry>       
      </collision>     -->
  </link>
  <joint name="$hand__end_effector_joint" type="fixed">
    <parent link="gripper_base_link"/>
    <child link="epick_end_effector"/>
    <origin rpy="0 0 0" xyz="0 0 0.187"/>
  </joint>
  <link name="epick_end_effector">
    <gravity>0</gravity>
    <visual>
      <origin rpy="0 0 0" xyz="0 0 .005"/>
      <geometry>
        <cylinder length="0.01" radius="0.0225"/>
      </geometry>
      <material name="transparent">
        <color rgba="0 0 1 1"/>
      </material>
    </visual>
    <collision>
      <origin rpy="0 0 0" xyz="0 0 .005"/>
      <geometry>
        <cylinder length="0.01" radius="0.0225"/>
      </geometry>
      <material name="transparent">
        <color rgba="0 0 1 1"/>
      </material>
    </collision>
    <inertial>
      <origin rpy="0 0 0" xyz="0 0 0"/>
      <mass value="0.0001"/>
      <inertia ixx="1e-08" ixy="0" ixz="0" iyy="1e-08" iyz="0" izz="1e-08"/>
    </inertial>
  </link>
  <!-- http://docs.ros.org/melodic/api/gazebo_plugins/html/group__GazeboRosVacuumGripper.html -->
  <gazebo>
    <plugin filename="libgazebo_ros_vacuum_gripper.so" name="gazebo_ros_vacuum_gripper">
      <robotNamespace>tahoma/epick</robotNamespace>
      <bodyName>epick_end_effector</bodyName>
      <topicName>grasping</topicName>
      <maxForce>20</maxForce>
      <maxDistance>0.03</maxDistance>
      <minDistance>0.01</minDistance>
    </plugin>
  </gazebo>
  <link name="base_link"/>
  <joint name="base_joint" type="fixed">
    <origin rpy="0 0 0" xyz="0 0 0.15"/>
    <parent link="base_link"/>
    <child link="stand"/>
  </joint>
  <joint name="robot_plate_arm_base_link_joint" type="fixed">
    <parent link="robot_plate"/>
    <child link="arm_base_link"/>
    <origin rpy="0 3.141592653589793 4.71238898038469" xyz="0 0.00175 -0.00885"/>
  </joint>
  <link name="coupling">
    <visual>
      <origin rpy="0 0 0" xyz="0 0 0"/>
      <geometry>
        <mesh filename="package://robotiq_2f_85_gripper_visualization/meshes/visual/coupling.stl"/>
      </geometry>
      <material name="">
        <color rgba="0.1 0.1 0.1 1"/>
      </material>
    </visual>
    <visual>
      <origin rpy="0 0 0" xyz="0.0335 0 0.006"/>
      <geometry>
        <mesh filename="package://robotiq_2f_85_gripper_visualization/meshes/visual/connector_cover.stl"/>
      </geometry>
      <material name="">
        <color rgba="0.1 0.1 0.1 1"/>
      </material>
    </visual>
    <collision>
      <!-- Primitives are centered, so offset -->
      <origin rpy="0 0 0" xyz="0.041 0 -0.013"/>
      <geometry>
        <box size=".015 0.033 .056"/>
      </geometry>
    </collision>
    <collision>
      <!-- Primitives are centered, so offset -->
      <origin rpy="0 0 0" xyz="0 0 0.00845"/>
      <geometry>
        <cylinder length=".0169" radius=".0375"/>
      </geometry>
    </collision>
  </link>
  <joint name="coupling_link_gripper_robotiq_arg2f_base_link_joint" type="fixed">
    <origin rpy="0 0 0" xyz="0 0 0.017"/>
    <parent link="coupling"/>
    <child link="gripper_base_link"/>
  </joint>
  <joint name="arm_tool0-coupling_joint" type="fixed">
    <origin rpy="0 0 4.71238898038469" xyz="0 0 -0.003"/>
    <parent link="arm_tool0"/>
    <child link="coupling"/>
  </joint>
  <link name="camera_lower_right_mount">
    <collision>
      <origin rpy="0 0 0" xyz="0 0 0"/>
      <geometry>
        <box size=".1 .15 .15"/>
      </geometry>
    </collision>
  </link>
  <link name="camera_lower_left_mount">
    <collision>
      <origin rpy="0 0 0" xyz="0 0 0"/>
      <geometry>
        <box size=".1 .15 .15"/>
      </geometry>
    </collision>
  </link>
  <joint name="camera_beam_lower_camera_lower_left_mount_joint" type="fixed">
    <parent link="camera_beam_lower"/>
    <child link="camera_lower_left_mount"/>
    <!-- Link is centered on the optical frames. Slight offset in Y direction to compensate -->
    <origin rpy="1.5707963267948966 0.2617993877991494 -0.1767088560700366" xyz="0.02 0.2285 0.14"/>
  </joint>
  <joint name="camera_beam_lower_camera_lower_right_mount_joint" type="fixed">
    <parent link="camera_beam_lower"/>
    <child link="camera_lower_right_mount"/>
    <origin rpy="1.5707963267948966 0.2617993877991494 0.1767088560700366" xyz="0.02 -0.2285 0.14"/>
  </joint>
  <!-- Upper cameras -->
  <!-- Link is centered on the optical frames. Slight offset in Y direction to compensate -->
  <!-- Z=1.10 for on top of the top beam -->
  <!-- Z=0.80 for underneath the top beam -->
  <!-- Disabled until we know about manipulability in upper bins
    <link name="camera_upper_right_mount"/>
    <link name="camera_upper_left_mount"/>
    <joint name="stand_upright_camera_upper_left_mount_joint" type="fixed">
      <parent link="stand_upright"/>
      <child link="camera_upper_left_mount"/>

      <origin xyz="-.1 ${-0.0215 + (camera_baseline / 2)} 0.80"
              rpy="${pi / 2} ${radians(15)} ${-atan2((camera_baseline /2),camera_focal_depth)}"/>
    </joint>
    <joint name="stand_upright_camera_upper_right_mount_joint" type="fixed">
      <parent link="stand_upright"/>
      <child link="camera_upper_right_mount"/>
      <origin xyz="-.1 ${0.0215 + (-camera_baseline / 2)} 0.80"
              rpy="${pi / 2} ${radians(15)} ${atan2((camera_baseline /2),camera_focal_depth)}"/>
    </joint>
    -->
  <link name="camera_upper_mount"/>
  <joint name="cantilever_camera_upper_mount_joint" type="fixed">
    <parent link="cantilever"/>
    <child link="camera_upper_mount"/>
    <origin rpy="0 0.2617993877991494 0" xyz=".02 0 0.37"/>
  </joint>
  <material name="black">
    <color rgba="0. 0. 0. 1"/>
  </material>
  <material name="dark_grey">
    <color rgba="0.1 0.1 0.1 1"/>
  </material>
  <material name="grey">
    <color rgba="0.6 0.6 0.6 1"/>
  </material>
  <material name="white">
    <color rgba="0.9 0.9 0.9 1"/>
  </material>
  <link name="camera_body">
    <visual>
      <origin xyz="0. 0. 0."/>
      <geometry>
        <box size="0.0994 0.0996 0.023"/>
      </geometry>
      <material name="white"/>
    </visual>
  </link>
  <link name="camera_base">
    <visual>
      <origin xyz="-0.013 0. 0."/>
      <geometry>
        <box size="0.026 0.103 0.039"/>
      </geometry>
      <material name="grey"/>
    </visual>
  </link>
  <link name="camera_visor">
    <visual>
      <origin xyz="-0.0128 0. 0."/>
      <geometry>
        <box size="0.026 0.101 0.037"/>
      </geometry>
      <material name="black"/>
    </visual>
  </link>
  <joint name="camera_base_to_body" type="fixed">
    <parent link="camera_base"/>
    <child link="camera_body"/>
    <origin rpy="0. 0. 0." xyz="-0.0757 0. 0.008"/>
  </joint>
  <joint name="camera_base_to_visor" type="fixed">
    <parent link="camera_base"/>
    <child link="camera_visor"/>
    <origin rpy="0. 0. 0." xyz="0. 0. 0."/>
  </joint>
  <joint name="kinect_base_joint" type="fixed">
    <parent link="base_link"/>
    <child link="camera_base"/>
    <!-- Link is centered on the optical frames. Slight offset in Y direction to compensate -->
    <origin rpy="3.13764 3.12912 -3.12899" xyz="-0.245645 -0.011721185 1.41034"/>
  </joint>
</robot>

